<mujoco model="walker2d">
    <compiler angle="radian" />
    <option timestep="0.004" integrator="RK4" />
    <size njmax="500" nconmax="100" />
    <default class="main">
        <joint limited="true" armature="0.01" damping="0.1" />
        <geom conaffinity="0" friction="0.7 0.1 0.1" rgba="0.8 0.6 0.4 1" />
    </default>
    <asset>
        <texture type="skybox" builtin="gradient" rgb1="0.4 0.5 0.6" rgb2="0 0 0" width="100" height="600" />
        <texture type="cube" name="texgeom" builtin="flat" mark="cross" rgb1="0.8 0.6 0.4" rgb2="0.8 0.6 0.4" markrgb="1 1 1" width="127" height="762" />
        <texture type="2d" name="texplane" builtin="checker" rgb1="0 0 0" rgb2="0.8 0.8 0.8" width="100" height="100" />
        <material name="MatPlane" texture="texplane" texrepeat="60 60" specular="1" shininess="1" reflectance="0.5" />
        <material name="geom" texture="texgeom" texuniform="true" />
    </asset>
    <worldbody>
        <geom name="floor" size="40 40 40" type="plane" conaffinity="1" material="MatPlane" rgba="0.8 0.9 0.8 1" />
        <light pos="0 0 1.3" dir="0 0 -1" directional="true" cutoff="100" exponent="1" diffuse="1 1 1" specular="0.1 0.1 0.1" />
        <body name="torso" pos="0 0 1.25">
            <inertial pos="0 0 0" mass="3.53429" diaginertia="0.0618501 0.0618501 0.00441786" />
            <joint name="rootx" pos="0 0 -1.25" axis="1 0 0" type="slide" limited="false" armature="0" damping="0" />
            <joint name="rootz" pos="0 0 -1.25" axis="0 0 1" type="slide" ref="1.25" limited="false" armature="0" damping="0" />
            <joint name="rooty" pos="0 0 0" axis="0 1 0" limited="false" armature="0" damping="0" />
            <geom name="torso_geom" size="0.05 0.2" type="capsule" friction="0.9 0.1 0.1" />
            <body name="thigh" pos="0 0 -0.2">
                <inertial pos="0 0 -0.225" mass="3.92699" diaginertia="0.0842667 0.0842667 0.00490874" />
                <joint name="thigh_joint" pos="0 0 0" axis="0 -1 0" range="-2.61799 0" />
                <geom name="thigh_geom" size="0.05 0.225" pos="0 0 -0.225" type="capsule" friction="0.9 0.1 0.1" />
                <body name="leg" pos="0 0 -0.7">
                    <inertial pos="0 0 0" mass="2.71434" diaginertia="0.0670441 0.0670441 0.00217147" />
                    <joint name="leg_joint" pos="0 0 0.25" axis="0 -1 0" range="-2.61799 0" />
                    <geom name="leg_geom" size="0.04 0.25" type="capsule" friction="0.9 0.1 0.1" />
                    <body name="foot" pos="0.2 0 -0.35">
                        <inertial pos="-0.1 0 0.1" quat="0.707107 0 -0.707107 0" mass="2.94053" diaginertia="0.0192115 0.0192115 0.00529296" />
                        <joint name="foot_joint" pos="-0.2 0 0.1" axis="0 -1 0" range="-0.785398 0.785398" />
                        <geom name="foot_geom" size="0.06 0.1" pos="-0.1 0 0.1" quat="0.707107 0 -0.707107 0" type="capsule" friction="0.9 0.1 0.1" />
                    </body>
                </body>
            </body>
            <body name="thigh_left" pos="0 0 -0.2">
                <inertial pos="0 0 -0.225" mass="3.92699" diaginertia="0.0842667 0.0842667 0.00490874" />
                <joint name="thigh_left_joint" pos="0 0 0" axis="0 -1 0" range="-2.61799 0" />
                <geom name="thigh_left_geom" size="0.05 0.225" pos="0 0 -0.225" type="capsule" friction="0.9 0.1 0.1" rgba="0.7 0.3 0.6 1" />
                <body name="leg_left" pos="0 0 -0.7">
                    <inertial pos="0 0 0" mass="2.71434" diaginertia="0.0670441 0.0670441 0.00217147" />
                    <joint name="leg_left_joint" pos="0 0 0.25" axis="0 -1 0" range="-2.61799 0" />
                    <geom name="leg_left_geom" size="0.04 0.25" type="capsule" friction="0.9 0.1 0.1" rgba="0.7 0.3 0.6 1" />
                    <body name="foot_left" pos="0.2 0 -0.35">
                        <inertial pos="-0.1 0 0.1" quat="0.707107 0 -0.707107 0" mass="2.94053" diaginertia="0.0192115 0.0192115 0.00529296" />
                        <joint name="foot_left_joint" pos="-0.2 0 0.1" axis="0 -1 0" range="-0.785398 0.785398" />
                        <geom name="foot_left_geom" size="0.06 0.1" pos="-0.1 0 0.1" quat="0.707107 0 -0.707107 0" type="capsule" friction="1.9 0.1 0.1" rgba="0.7 0.3 0.6 1" />
                    </body>
                </body>
            </body>
        </body>
    </worldbody>
    <actuator>
        <general joint="thigh_joint" ctrllimited="true" ctrlrange="-1 1" gear="100 0 0 0 0 0" />
        <general joint="leg_joint" ctrllimited="true" ctrlrange="-1 1" gear="100 0 0 0 0 0" />
        <general joint="foot_joint" ctrllimited="true" ctrlrange="-1 1" gear="100 0 0 0 0 0" />
        <general joint="thigh_left_joint" ctrllimited="true" ctrlrange="-1 1" gear="100 0 0 0 0 0" />
        <general joint="leg_left_joint" ctrllimited="true" ctrlrange="-1 1" gear="100 0 0 0 0 0" />
        <general joint="foot_left_joint" ctrllimited="true" ctrlrange="-1 1" gear="100 0 0 0 0 0" />
    </actuator>
</mujoco>
